2025-08-11 20:47:51,538 - __main__ - INFO - Checking YouTube connectivity...
2025-08-11 20:47:51,539 - __main__ - ERROR - YouTube connectivity check failed: AsyncClient.__init__() got an unexpected keyword argument 'proxies'
2025-08-11 20:50:33,639 - httpx - INFO - HTTP Request: POST https://api.telegram.org/bot7915543950:AAGlBZ4lL2qzkoSVQlYQyMloc1D5o1P52fo/getMe "HTTP/1.1 200 OK"
2025-08-11 20:50:33,640 - __main__ - INFO - Checking YouTube connectivity...
2025-08-11 20:50:33,640 - __main__ - ERROR - YouTube connectivity check failed: AsyncClient.__init__() got an unexpected keyword argument 'proxies'
2025-08-11 20:50:33,705 - httpx - INFO - HTTP Request: POST https://api.telegram.org/bot7915543950:AAGlBZ4lL2qzkoSVQlYQyMloc1D5o1P52fo/deleteWebhook "HTTP/1.1 200 OK"
2025-08-11 20:50:33,707 - telegram.ext.Application - INFO - Application started
2025-08-11 20:50:43,919 - httpx - INFO - HTTP Request: POST https://api.telegram.org/bot7915543950:AAGlBZ4lL2qzkoSVQlYQyMloc1D5o1P52fo/getUpdates "HTTP/1.1 200 OK"
2025-08-11 20:50:53,993 - httpx - INFO - HTTP Request: POST https://api.telegram.org/bot7915543950:AAGlBZ4lL2qzkoSVQlYQyMloc1D5o1P52fo/getUpdates "HTTP/1.1 200 OK"
2025-08-11 20:51:04,058 - httpx - INFO - HTTP Request: POST https://api.telegram.org/bot7915543950:AAGlBZ4lL2qzkoSVQlYQyMloc1D5o1P52fo/getUpdates "HTTP/1.1 200 OK"
2025-08-11 20:51:13,764 - httpx - INFO - HTTP Request: POST https://api.telegram.org/bot7915543950:AAGlBZ4lL2qzkoSVQlYQyMloc1D5o1P52fo/getUpdates "HTTP/1.1 200 OK"
2025-08-11 20:51:14,955 - httpx - INFO - HTTP Request: POST https://api.telegram.org/bot7915543950:AAGlBZ4lL2qzkoSVQlYQyMloc1D5o1P52fo/answerCallbackQuery "HTTP/1.1 200 OK"
2025-08-11 20:51:15,100 - httpx - INFO - HTTP Request: POST https://api.telegram.org/bot7915543950:AAGlBZ4lL2qzkoSVQlYQyMloc1D5o1P52fo/sendMessage "HTTP/1.1 200 OK"
2025-08-11 20:51:24,000 - httpx - INFO - HTTP Request: POST https://api.telegram.org/bot7915543950:AAGlBZ4lL2qzkoSVQlYQyMloc1D5o1P52fo/getUpdates "HTTP/1.1 200 OK"
2025-08-11 20:51:34,198 - httpx - INFO - HTTP Request: POST https://api.telegram.org/bot7915543950:AAGlBZ4lL2qzkoSVQlYQyMloc1D5o1P52fo/getUpdates "HTTP/1.1 200 OK"
2025-08-11 20:51:44,311 - httpx - INFO - HTTP Request: POST https://api.telegram.org/bot7915543950:AAGlBZ4lL2qzkoSVQlYQyMloc1D5o1P52fo/getUpdates "HTTP/1.1 200 OK"
2025-08-11 20:51:54,477 - httpx - INFO - HTTP Request: POST https://api.telegram.org/bot7915543950:AAGlBZ4lL2qzkoSVQlYQyMloc1D5o1P52fo/getUpdates "HTTP/1.1 200 OK"
2025-08-11 20:52:04,797 - httpx - INFO - HTTP Request: POST https://api.telegram.org/bot7915543950:AAGlBZ4lL2qzkoSVQlYQyMloc1D5o1P52fo/getUpdates "HTTP/1.1 200 OK"
2025-08-11 20:52:12,883 - httpx - INFO - HTTP Request: POST https://api.telegram.org/bot7915543950:AAGlBZ4lL2qzkoSVQlYQyMloc1D5o1P52fo/getUpdates "HTTP/1.1 200 OK"
2025-08-11 20:52:13,811 - httpx - INFO - HTTP Request: POST https://api.telegram.org/bot7915543950:AAGlBZ4lL2qzkoSVQlYQyMloc1D5o1P52fo/answerCallbackQuery "HTTP/1.1 200 OK"
2025-08-11 20:52:13,811 - __main__ - INFO - Checking YouTube connectivity...
2025-08-11 20:52:13,811 - __main__ - ERROR - YouTube connectivity check failed: AsyncClient.__init__() got an unexpected keyword argument 'proxies'
2025-08-11 20:52:14,011 - httpx - INFO - HTTP Request: POST https://api.telegram.org/bot7915543950:AAGlBZ4lL2qzkoSVQlYQyMloc1D5o1P52fo/sendMessage "HTTP/1.1 200 OK"
2025-08-11 20:52:23,054 - httpx - INFO - HTTP Request: POST https://api.telegram.org/bot7915543950:AAGlBZ4lL2qzkoSVQlYQyMloc1D5o1P52fo/getUpdates "HTTP/1.1 200 OK"
2025-08-11 20:52:33,170 - httpx - INFO - HTTP Request: POST https://api.telegram.org/bot7915543950:AAGlBZ4lL2qzkoSVQlYQyMloc1D5o1P52fo/getUpdates "HTTP/1.1 200 OK"
2025-08-11 20:52:43,239 - httpx - INFO - HTTP Request: POST https://api.telegram.org/bot7915543950:AAGlBZ4lL2qzkoSVQlYQyMloc1D5o1P52fo/getUpdates "HTTP/1.1 200 OK"
2025-08-11 20:52:53,344 - httpx - INFO - HTTP Request: POST https://api.telegram.org/bot7915543950:AAGlBZ4lL2qzkoSVQlYQyMloc1D5o1P52fo/getUpdates "HTTP/1.1 200 OK"
2025-08-11 20:53:03,608 - httpx - INFO - HTTP Request: POST https://api.telegram.org/bot7915543950:AAGlBZ4lL2qzkoSVQlYQyMloc1D5o1P52fo/getUpdates "HTTP/1.1 200 OK"
2025-08-11 20:53:13,740 - httpx - INFO - HTTP Request: POST https://api.telegram.org/bot7915543950:AAGlBZ4lL2qzkoSVQlYQyMloc1D5o1P52fo/getUpdates "HTTP/1.1 200 OK"
2025-08-11 20:53:23,845 - httpx - INFO - HTTP Request: POST https://api.telegram.org/bot7915543950:AAGlBZ4lL2qzkoSVQlYQyMloc1D5o1P52fo/getUpdates "HTTP/1.1 200 OK"
2025-08-11 20:53:33,913 - httpx - INFO - HTTP Request: POST https://api.telegram.org/bot7915543950:AAGlBZ4lL2qzkoSVQlYQyMloc1D5o1P52fo/getUpdates "HTTP/1.1 200 OK"
2025-08-11 20:53:43,982 - httpx - INFO - HTTP Request: POST https://api.telegram.org/bot7915543950:AAGlBZ4lL2qzkoSVQlYQyMloc1D5o1P52fo/getUpdates "HTTP/1.1 200 OK"
2025-08-11 20:53:44,586 - telegram.ext.Application - ERROR - No error handlers are registered, logging exception.
Traceback (most recent call last):
  File "C:\Users\tyca7\AppData\Local\Programs\Python\Python313\Lib\site-packages\httpx\_transports\default.py", line 101, in map_httpcore_exceptions
    yield
  File "C:\Users\tyca7\AppData\Local\Programs\Python\Python313\Lib\site-packages\httpx\_transports\default.py", line 394, in handle_async_request
    resp = await self._pool.handle_async_request(req)
           ^^^^^^^^^^^^^^^^^^^^^^^^^^^^^^^^^^^^^^^^^^
  File "C:\Users\tyca7\AppData\Local\Programs\Python\Python313\Lib\site-packages\httpcore\_async\connection_pool.py", line 256, in handle_async_request
    raise exc from None
  File "C:\Users\tyca7\AppData\Local\Programs\Python\Python313\Lib\site-packages\httpcore\_async\connection_pool.py", line 236, in handle_async_request
    response = await connection.handle_async_request(
               ^^^^^^^^^^^^^^^^^^^^^^^^^^^^^^^^^^^^^^
        pool_request.request
        ^^^^^^^^^^^^^^^^^^^^
    )
    ^
  File "C:\Users\tyca7\AppData\Local\Programs\Python\Python313\Lib\site-packages\httpcore\_async\connection.py", line 103, in handle_async_request
    return await self._connection.handle_async_request(request)
           ^^^^^^^^^^^^^^^^^^^^^^^^^^^^^^^^^^^^^^^^^^^^^^^^^^^^
  File "C:\Users\tyca7\AppData\Local\Programs\Python\Python313\Lib\site-packages\httpcore\_async\http11.py", line 136, in handle_async_request
    raise exc
  File "C:\Users\tyca7\AppData\Local\Programs\Python\Python313\Lib\site-packages\httpcore\_async\http11.py", line 106, in handle_async_request
    ) = await self._receive_response_headers(**kwargs)
        ^^^^^^^^^^^^^^^^^^^^^^^^^^^^^^^^^^^^^^^^^^^^^^
  File "C:\Users\tyca7\AppData\Local\Programs\Python\Python313\Lib\site-packages\httpcore\_async\http11.py", line 177, in _receive_response_headers
    event = await self._receive_event(timeout=timeout)
            ^^^^^^^^^^^^^^^^^^^^^^^^^^^^^^^^^^^^^^^^^^
  File "C:\Users\tyca7\AppData\Local\Programs\Python\Python313\Lib\site-packages\httpcore\_async\http11.py", line 217, in _receive_event
    data = await self._network_stream.read(
           ^^^^^^^^^^^^^^^^^^^^^^^^^^^^^^^^
        self.READ_NUM_BYTES, timeout=timeout
        ^^^^^^^^^^^^^^^^^^^^^^^^^^^^^^^^^^^^
    )
    ^
  File "C:\Users\tyca7\AppData\Local\Programs\Python\Python313\Lib\site-packages\httpcore\_backends\anyio.py", line 32, in read
    with map_exceptions(exc_map):
         ~~~~~~~~~~~~~~^^^^^^^^^
  File "C:\Users\tyca7\AppData\Local\Programs\Python\Python313\Lib\contextlib.py", line 162, in __exit__
    self.gen.throw(value)
    ~~~~~~~~~~~~~~^^^^^^^
  File "C:\Users\tyca7\AppData\Local\Programs\Python\Python313\Lib\site-packages\httpcore\_exceptions.py", line 14, in map_exceptions
    raise to_exc(exc) from exc
httpcore.ReadError

The above exception was the direct cause of the following exception:

Traceback (most recent call last):
  File "C:\Users\tyca7\AppData\Local\Programs\Python\Python313\Lib\site-packages\telegram\request\_httpxrequest.py", line 273, in do_request
    res = await self._client.request(
          ^^^^^^^^^^^^^^^^^^^^^^^^^^^
    ...<6 lines>...
    )
    ^
  File "C:\Users\tyca7\AppData\Local\Programs\Python\Python313\Lib\site-packages\httpx\_client.py", line 1540, in request
    return await self.send(request, auth=auth, follow_redirects=follow_redirects)
           ^^^^^^^^^^^^^^^^^^^^^^^^^^^^^^^^^^^^^^^^^^^^^^^^^^^^^^^^^^^^^^^^^^^^^^
  File "C:\Users\tyca7\AppData\Local\Programs\Python\Python313\Lib\site-packages\httpx\_client.py", line 1629, in send
    response = await self._send_handling_auth(
               ^^^^^^^^^^^^^^^^^^^^^^^^^^^^^^^
    ...<4 lines>...
    )
    ^
  File "C:\Users\tyca7\AppData\Local\Programs\Python\Python313\Lib\site-packages\httpx\_client.py", line 1657, in _send_handling_auth
    response = await self._send_handling_redirects(
               ^^^^^^^^^^^^^^^^^^^^^^^^^^^^^^^^^^^^
    ...<3 lines>...
    )
    ^
  File "C:\Users\tyca7\AppData\Local\Programs\Python\Python313\Lib\site-packages\httpx\_client.py", line 1694, in _send_handling_redirects
    response = await self._send_single_request(request)
               ^^^^^^^^^^^^^^^^^^^^^^^^^^^^^^^^^^^^^^^^
  File "C:\Users\tyca7\AppData\Local\Programs\Python\Python313\Lib\site-packages\httpx\_client.py", line 1730, in _send_single_request
    response = await transport.handle_async_request(request)
               ^^^^^^^^^^^^^^^^^^^^^^^^^^^^^^^^^^^^^^^^^^^^^
  File "C:\Users\tyca7\AppData\Local\Programs\Python\Python313\Lib\site-packages\httpx\_transports\default.py", line 393, in handle_async_request
    with map_httpcore_exceptions():
         ~~~~~~~~~~~~~~~~~~~~~~~^^
  File "C:\Users\tyca7\AppData\Local\Programs\Python\Python313\Lib\contextlib.py", line 162, in __exit__
    self.gen.throw(value)
    ~~~~~~~~~~~~~~^^^^^^^
  File "C:\Users\tyca7\AppData\Local\Programs\Python\Python313\Lib\site-packages\httpx\_transports\default.py", line 118, in map_httpcore_exceptions
    raise mapped_exc(message) from exc
httpx.ReadError

The above exception was the direct cause of the following exception:

Traceback (most recent call last):
  File "C:\Users\tyca7\AppData\Local\Programs\Python\Python313\Lib\site-packages\telegram\ext\_utils\networkloop.py", line 115, in network_retry_loop
    if not await do_action():
           ^^^^^^^^^^^^^^^^^
  File "C:\Users\tyca7\AppData\Local\Programs\Python\Python313\Lib\site-packages\telegram\ext\_utils\networkloop.py", line 108, in do_action
    return action_cb_task.result()
           ~~~~~~~~~~~~~~~~~~~~~^^
  File "C:\Users\tyca7\AppData\Local\Programs\Python\Python313\Lib\site-packages\telegram\ext\_updater.py", line 340, in polling_action_cb
    updates = await self.bot.get_updates(
              ^^^^^^^^^^^^^^^^^^^^^^^^^^^
    ...<3 lines>...
    )
    ^
  File "C:\Users\tyca7\AppData\Local\Programs\Python\Python313\Lib\site-packages\telegram\ext\_extbot.py", line 670, in get_updates
    updates = await super().get_updates(
              ^^^^^^^^^^^^^^^^^^^^^^^^^^
    ...<9 lines>...
    )
    ^
  File "C:\Users\tyca7\AppData\Local\Programs\Python\Python313\Lib\site-packages\telegram\_bot.py", line 4611, in get_updates
    await self._post(
    ^^^^^^^^^^^^^^^^^
    ...<7 lines>...
    ),
    ^
  File "C:\Users\tyca7\AppData\Local\Programs\Python\Python313\Lib\site-packages\telegram\_bot.py", line 698, in _post
    return await self._do_post(
           ^^^^^^^^^^^^^^^^^^^^
    ...<6 lines>...
    )
    ^
  File "C:\Users\tyca7\AppData\Local\Programs\Python\Python313\Lib\site-packages\telegram\ext\_extbot.py", line 370, in _do_post
    return await super()._do_post(
           ^^^^^^^^^^^^^^^^^^^^^^^
    ...<6 lines>...
    )
    ^
  File "C:\Users\tyca7\AppData\Local\Programs\Python\Python313\Lib\site-packages\telegram\_bot.py", line 727, in _do_post
    result = await request.post(
             ^^^^^^^^^^^^^^^^^^^
    ...<6 lines>...
    )
    ^
  File "C:\Users\tyca7\AppData\Local\Programs\Python\Python313\Lib\site-packages\telegram\request\_baserequest.py", line 197, in post
    result = await self._request_wrapper(
             ^^^^^^^^^^^^^^^^^^^^^^^^^^^^
    ...<7 lines>...
    )
    ^
  File "C:\Users\tyca7\AppData\Local\Programs\Python\Python313\Lib\site-packages\telegram\request\_baserequest.py", line 304, in _request_wrapper
    code, payload = await self.do_request(
                    ^^^^^^^^^^^^^^^^^^^^^^
    ...<7 lines>...
    )
    ^
  File "C:\Users\tyca7\AppData\Local\Programs\Python\Python313\Lib\site-packages\telegram\request\_httpxrequest.py", line 297, in do_request
    raise NetworkError(f"httpx.{err.__class__.__name__}: {err}") from err
telegram.error.NetworkError: httpx.ReadError: 
2025-08-11 20:53:55,762 - httpx - INFO - HTTP Request: POST https://api.telegram.org/bot7915543950:AAGlBZ4lL2qzkoSVQlYQyMloc1D5o1P52fo/getUpdates "HTTP/1.1 200 OK"
2025-08-11 20:54:05,813 - httpx - INFO - HTTP Request: POST https://api.telegram.org/bot7915543950:AAGlBZ4lL2qzkoSVQlYQyMloc1D5o1P52fo/getUpdates "HTTP/1.1 200 OK"
2025-08-11 20:54:15,863 - httpx - INFO - HTTP Request: POST https://api.telegram.org/bot7915543950:AAGlBZ4lL2qzkoSVQlYQyMloc1D5o1P52fo/getUpdates "HTTP/1.1 200 OK"
2025-08-11 20:54:25,915 - httpx - INFO - HTTP Request: POST https://api.telegram.org/bot7915543950:AAGlBZ4lL2qzkoSVQlYQyMloc1D5o1P52fo/getUpdates "HTTP/1.1 200 OK"
2025-08-11 20:54:35,972 - httpx - INFO - HTTP Request: POST https://api.telegram.org/bot7915543950:AAGlBZ4lL2qzkoSVQlYQyMloc1D5o1P52fo/getUpdates "HTTP/1.1 200 OK"
2025-08-11 20:54:46,023 - httpx - INFO - HTTP Request: POST https://api.telegram.org/bot7915543950:AAGlBZ4lL2qzkoSVQlYQyMloc1D5o1P52fo/getUpdates "HTTP/1.1 200 OK"
2025-08-11 20:54:56,073 - httpx - INFO - HTTP Request: POST https://api.telegram.org/bot7915543950:AAGlBZ4lL2qzkoSVQlYQyMloc1D5o1P52fo/getUpdates "HTTP/1.1 200 OK"
2025-08-11 20:55:06,123 - httpx - INFO - HTTP Request: POST https://api.telegram.org/bot7915543950:AAGlBZ4lL2qzkoSVQlYQyMloc1D5o1P52fo/getUpdates "HTTP/1.1 200 OK"
2025-08-11 20:55:16,176 - httpx - INFO - HTTP Request: POST https://api.telegram.org/bot7915543950:AAGlBZ4lL2qzkoSVQlYQyMloc1D5o1P52fo/getUpdates "HTTP/1.1 200 OK"
2025-08-11 21:27:04,679 - httpx - INFO - HTTP Request: POST https://api.telegram.org/bot7915543950:AAGlBZ4lL2qzkoSVQlYQyMloc1D5o1P52fo/getMe "HTTP/1.1 200 OK"
2025-08-11 21:27:04,679 - __main__ - INFO - Checking YouTube connectivity...
2025-08-11 21:27:24,148 - __main__ - ERROR - YouTube connectivity check failed: 
2025-08-11 21:27:24,301 - httpx - INFO - HTTP Request: POST https://api.telegram.org/bot7915543950:AAGlBZ4lL2qzkoSVQlYQyMloc1D5o1P52fo/deleteWebhook "HTTP/1.1 200 OK"
2025-08-11 21:27:24,302 - telegram.ext.Application - INFO - Application started
